----------------------------------------
Exception happened during processing of request from ('172.22.22.3', 39303)
Traceback (most recent call last):
  File "/usr/lib/python2.7/SocketServer.py", line 293, in _handle_request_noblock
    self.process_request(request, client_address)
  File "/usr/lib/python2.7/SocketServer.py", line 321, in process_request
    self.finish_request(request, client_address)
  File "/usr/lib/python2.7/SocketServer.py", line 334, in finish_request
    self.RequestHandlerClass(request, client_address, self)
  File "/usr/lib/python2.7/SocketServer.py", line 655, in __init__
    self.handle()
  File "/home/bdml/ae_ws/bdml_ur5_actual_dooropening/src/universal_robot/ur_driver/src/ur_driver/driver.py", line 461, in handle
    buf = buf + self.recv_more()
  File "/home/bdml/ae_ws/bdml_ur5_actual_dooropening/src/universal_robot/ur_driver/src/ur_driver/driver.py", line 409, in recv_more
    more = self.request.recv(4096)
error: [Errno 104] Connection reset by peer
----------------------------------------
